Workbook

Sheet Trade Log
A1: Trade # | B1: Date | C1: Time | D1: Symbol | E1: Book | F1: Setup | G1: Quality | H1: Regime | I1: Entry Price | J1: Stop Price | K1: Risk ($) | L1: Shares | M1: Exit Price | N1: Exit Time | O1: Exit Reason | P1: Bars Held | Q1: PnL (pts) | R1: PnL (R) | S1: PnL ($) | T1: Cum R | U1: Notes | V1: Tape Perm
A2: =IF(B2="","",ROW()-1) | L2: =IF(AND(I2<>"",J2<>"",K2<>""),ROUND(K2/ABS(I2-J2),0),"") | Q2: =IF(AND(M2<>"",I2<>""),IF(E2="LONG",M2-I2,I2-M2),"") | R2: =IF(AND(Q2<>"",I2<>"",J2<>""),Q2/ABS(I2-J2),"") | S2: =IF(AND(R2<>"",K2<>""),R2*K2,"") | T2: =IF(R2<>"",R2,"")
A3: =IF(B3="","",ROW()-1) | L3: =IF(AND(I3<>"",J3<>"",K3<>""),ROUND(K3/ABS(I3-J3),0),"") | Q3: =IF(AND(M3<>"",I3<>""),IF(E3="LONG",M3-I3,I3-M3),"") | R3: =IF(AND(Q3<>"",I3<>"",J3<>""),Q3/ABS(I3-J3),"") | S3: =IF(AND(R3<>"",K3<>""),R3*K3,"") | T3: =IF(R3<>"",T2+R3,"")
A4: =IF(B4="","",ROW()-1) | L4: =IF(AND(I4<>"",J4<>"",K4<>""),ROUND(K4/ABS(I4-J4),0),"") | Q4: =IF(AND(M4<>"",I4<>""),IF(E4="LONG",M4-I4,I4-M4),"") | R4: =IF(AND(Q4<>"",I4<>"",J4<>""),Q4/ABS(I4-J4),"") | S4: =IF(AND(R4<>"",K4<>""),R4*K4,"") | T4: =IF(R4<>"",T3+R4,"")
A5: =IF(B5="","",ROW()-1) | L5: =IF(AND(I5<>"",J5<>"",K5<>""),ROUND(K5/ABS(I5-J5),0),"") | Q5: =IF(AND(M5<>"",I5<>""),IF(E5="LONG",M5-I5,I5-M5),"") | R5: =IF(AND(Q5<>"",I5<>"",J5<>""),Q5/ABS(I5-J5),"") | S5: =IF(AND(R5<>"",K5<>""),R5*K5,"") | T5: =IF(R5<>"",T4+R5,"")
A6: =IF(B6="","",ROW()-1) | L6: =IF(AND(I6<>"",J6<>"",K6<>""),ROUND(K6/ABS(I6-J6),0),"") | Q6: =IF(AND(M6<>"",I6<>""),IF(E6="LONG",M6-I6,I6-M6),"") | R6: =IF(AND(Q6<>"",I6<>"",J6<>""),Q6/ABS(I6-J6),"") | S6: =IF(AND(R6<>"",K6<>""),R6*K6,"") | T6: =IF(R6<>"",T5+R6,"")
A7: =IF(B7="","",ROW()-1) | L7: =IF(AND(I7<>"",J7<>"",K7<>""),ROUND(K7/ABS(I7-J7),0),"") | Q7: =IF(AND(M7<>"",I7<>""),IF(E7="LONG",M7-I7,I7-M7),"") | R7: =IF(AND(Q7<>"",I7<>"",J7<>""),Q7/ABS(I7-J7),"") | S7: =IF(AND(R7<>"",K7<>""),R7*K7,"") | T7: =IF(R7<>"",T6+R7,"")
A8: =IF(B8="","",ROW()-1) | L8: =IF(AND(I8<>"",J8<>"",K8<>""),ROUND(K8/ABS(I8-J8),0),"") | Q8: =IF(AND(M8<>"",I8<>""),IF(E8="LONG",M8-I8,I8-M8),"") | R8: =IF(AND(Q8<>"",I8<>"",J8<>""),Q8/ABS(I8-J8),"") | S8: =IF(AND(R8<>"",K8<>""),R8*K8,"") | T8: =IF(R8<>"",T7+R8,"")
A9: =IF(B9="","",ROW()-1) | L9: =IF(AND(I9<>"",J9<>"",K9<>""),ROUND(K9/ABS(I9-J9),0),"") | Q9: =IF(AND(M9<>"",I9<>""),IF(E9="LONG",M9-I9,I9-M9),"") | R9: =IF(AND(Q9<>"",I9<>"",J9<>""),Q9/ABS(I9-J9),"") | S9: =IF(AND(R9<>"",K9<>""),R9*K9,"") | T9: =IF(R9<>"",T8+R9,"")
A10: =IF(B10="","",ROW()-1) | L10: =IF(AND(I10<>"",J10<>"",K10<>""),ROUND(K10/ABS(I10-J10),0),"") | Q10: =IF(AND(M10<>"",I10<>""),IF(E10="LONG",M10-I10,I10-M10),"") | R10: =IF(AND(Q10<>"",I10<>"",J10<>""),Q10/ABS(I10-J10),"") | S10: =IF(AND(R10<>"",K10<>""),R10*K10,"") | T10: =IF(R10<>"",T9+R10,"")
A11: =IF(B11="","",ROW()-1) | L11: =IF(AND(I11<>"",J11<>"",K11<>""),ROUND(K11/ABS(I11-J11),0),"") | Q11: =IF(AND(M11<>"",I11<>""),IF(E11="LONG",M11-I11,I11-M11),"") | R11: =IF(AND(Q11<>"",I11<>"",J11<>""),Q11/ABS(I11-J11),"") | S11: =IF(AND(R11<>"",K11<>""),R11*K11,"") | T11: =IF(R11<>"",T10+R11,"")
A12: =IF(B12="","",ROW()-1) | L12: =IF(AND(I12<>"",J12<>"",K12<>""),ROUND(K12/ABS(I12-J12),0),"") | Q12: =IF(AND(M12<>"",I12<>""),IF(E12="LONG",M12-I12,I12-M12),"") | R12: =IF(AND(Q12<>"",I12<>"",J12<>""),Q12/ABS(I12-J12),"") | S12: =IF(AND(R12<>"",K12<>""),R12*K12,"") | T12: =IF(R12<>"",T11+R12,"")
A13: =IF(B13="","",ROW()-1) | L13: =IF(AND(I13<>"",J13<>"",K13<>""),ROUND(K13/ABS(I13-J13),0),"") | Q13: =IF(AND(M13<>"",I13<>""),IF(E13="LONG",M13-I13,I13-M13),"") | R13: =IF(AND(Q13<>"",I13<>"",J13<>""),Q13/ABS(I13-J13),"") | S13: =IF(AND(R13<>"",K13<>""),R13*K13,"") | T13: =IF(R13<>"",T12+R13,"")
A14: =IF(B14="","",ROW()-1) | L14: =IF(AND(I14<>"",J14<>"",K14<>""),ROUND(K14/ABS(I14-J14),0),"") | Q14: =IF(AND(M14<>"",I14<>""),IF(E14="LONG",M14-I14,I14-M14),"") | R14: =IF(AND(Q14<>"",I14<>"",J14<>""),Q14/ABS(I14-J14),"") | S14: =IF(AND(R14<>"",K14<>""),R14*K14,"") | T14: =IF(R14<>"",T13+R14,"")
... A201: =IF(B201="","",ROW()-1) | L201: =IF(AND(I201<>"",J201<>"",K201<>""),ROUND(K201/ABS(I201-J201),0),"") | Q201: =IF(AND(M201<>"",I201<>""),IF(E201="LONG",M201-I201,I201-M201),"") | R201: =IF(AND(Q201<>"",I201<>"",J201<>""),Q201/ABS(I201-J201),"") | S201: =IF(AND(R201<>"",K201<>""),R201*K201,"") | T201: =IF(R201<>"",T200+R201,"")

Sheet Daily Summary
A1: Date | B1: Regime | C1: SPY Chg% | D1: Long Trades | E1: Short Trades | F1: Long R | G1: Short R | H1: Day R | I1: Cum R | J1: Max Concurrency | K1: Notes
D2: =IF(A2="","",COUNTIFS('Trade Log'!B$2:B$201,A2,'Trade Log'!E$2:E$201,"LONG")) | E2: =IF(A2="","",COUNTIFS('Trade Log'!B$2:B$201,A2,'Trade Log'!E$2:E$201,"SHORT")) | F2: =IF(A2="","",SUMIFS('Trade Log'!R$2:R$201,'Trade Log'!B$2:B$201,A2,'Trade Log'!E$2:E$201,"LONG")) | G2: =IF(A2="","",SUMIFS('Trade Log'!R$2:R$201,'Trade Log'!B$2:B$201,A2,'Trade Log'!E$2:E$201,"SHORT")) | H2: =IF(A2="","",F2+G2) | I2: =IF(A2="","",H2)
D3: =IF(A3="","",COUNTIFS('Trade Log'!B$2:B$201,A3,'Trade Log'!E$2:E$201,"LONG")) | E3: =IF(A3="","",COUNTIFS('Trade Log'!B$2:B$201,A3,'Trade Log'!E$2:E$201,"SHORT")) | F3: =IF(A3="","",SUMIFS('Trade Log'!R$2:R$201,'Trade Log'!B$2:B$201,A3,'Trade Log'!E$2:E$201,"LONG")) | G3: =IF(A3="","",SUMIFS('Trade Log'!R$2:R$201,'Trade Log'!B$2:B$201,A3,'Trade Log'!E$2:E$201,"SHORT")) | H3: =IF(A3="","",F3+G3) | I3: =IF(A3="","",I2+H3)
D4: =IF(A4="","",COUNTIFS('Trade Log'!B$2:B$201,A4,'Trade Log'!E$2:E$201,"LONG")) | E4: =IF(A4="","",COUNTIFS('Trade Log'!B$2:B$201,A4,'Trade Log'!E$2:E$201,"SHORT")) | F4: =IF(A4="","",SUMIFS('Trade Log'!R$2:R$201,'Trade Log'!B$2:B$201,A4,'Trade Log'!E$2:E$201,"LONG")) | G4: =IF(A4="","",SUMIFS('Trade Log'!R$2:R$201,'Trade Log'!B$2:B$201,A4,'Trade Log'!E$2:E$201,"SHORT")) | H4: =IF(A4="","",F4+G4) | I4: =IF(A4="","",I3+H4)
D5: =IF(A5="","",COUNTIFS('Trade Log'!B$2:B$201,A5,'Trade Log'!E$2:E$201,"LONG")) | E5: =IF(A5="","",COUNTIFS('Trade Log'!B$2:B$201,A5,'Trade Log'!E$2:E$201,"SHORT")) | F5: =IF(A5="","",SUMIFS('Trade Log'!R$2:R$201,'Trade Log'!B$2:B$201,A5,'Trade Log'!E$2:E$201,"LONG")) | G5: =IF(A5="","",SUMIFS('Trade Log'!R$2:R$201,'Trade Log'!B$2:B$201,A5,'Trade Log'!E$2:E$201,"SHORT")) | H5: =IF(A5="","",F5+G5) | I5: =IF(A5="","",I4+H5)
D6: =IF(A6="","",COUNTIFS('Trade Log'!B$2:B$201,A6,'Trade Log'!E$2:E$201,"LONG")) | E6: =IF(A6="","",COUNTIFS('Trade Log'!B$2:B$201,A6,'Trade Log'!E$2:E$201,"SHORT")) | F6: =IF(A6="","",SUMIFS('Trade Log'!R$2:R$201,'Trade Log'!B$2:B$201,A6,'Trade Log'!E$2:E$201,"LONG")) | G6: =IF(A6="","",SUMIFS('Trade Log'!R$2:R$201,'Trade Log'!B$2:B$201,A6,'Trade Log'!E$2:E$201,"SHORT")) | H6: =IF(A6="","",F6+G6) | I6: =IF(A6="","",I5+H6)
D7: =IF(A7="","",COUNTIFS('Trade Log'!B$2:B$201,A7,'Trade Log'!E$2:E$201,"LONG")) | E7: =IF(A7="","",COUNTIFS('Trade Log'!B$2:B$201,A7,'Trade Log'!E$2:E$201,"SHORT")) | F7: =IF(A7="","",SUMIFS('Trade Log'!R$2:R$201,'Trade Log'!B$2:B$201,A7,'Trade Log'!E$2:E$201,"LONG")) | G7: =IF(A7="","",SUMIFS('Trade Log'!R$2:R$201,'Trade Log'!B$2:B$201,A7,'Trade Log'!E$2:E$201,"SHORT")) | H7: =IF(A7="","",F7+G7) | I7: =IF(A7="","",I6+H7)
D8: =IF(A8="","",COUNTIFS('Trade Log'!B$2:B$201,A8,'Trade Log'!E$2:E$201,"LONG")) | E8: =IF(A8="","",COUNTIFS('Trade Log'!B$2:B$201,A8,'Trade Log'!E$2:E$201,"SHORT")) | F8: =IF(A8="","",SUMIFS('Trade Log'!R$2:R$201,'Trade Log'!B$2:B$201,A8,'Trade Log'!E$2:E$201,"LONG")) | G8: =IF(A8="","",SUMIFS('Trade Log'!R$2:R$201,'Trade Log'!B$2:B$201,A8,'Trade Log'!E$2:E$201,"SHORT")) | H8: =IF(A8="","",F8+G8) | I8: =IF(A8="","",I7+H8)
D9: =IF(A9="","",COUNTIFS('Trade Log'!B$2:B$201,A9,'Trade Log'!E$2:E$201,"LONG")) | E9: =IF(A9="","",COUNTIFS('Trade Log'!B$2:B$201,A9,'Trade Log'!E$2:E$201,"SHORT")) | F9: =IF(A9="","",SUMIFS('Trade Log'!R$2:R$201,'Trade Log'!B$2:B$201,A9,'Trade Log'!E$2:E$201,"LONG")) | G9: =IF(A9="","",SUMIFS('Trade Log'!R$2:R$201,'Trade Log'!B$2:B$201,A9,'Trade Log'!E$2:E$201,"SHORT")) | H9: =IF(A9="","",F9+G9) | I9: =IF(A9="","",I8+H9)
D10: =IF(A10="","",COUNTIFS('Trade Log'!B$2:B$201,A10,'Trade Log'!E$2:E$201,"LONG")) | E10: =IF(A10="","",COUNTIFS('Trade Log'!B$2:B$201,A10,'Trade Log'!E$2:E$201,"SHORT")) | F10: =IF(A10="","",SUMIFS('Trade Log'!R$2:R$201,'Trade Log'!B$2:B$201,A10,'Trade Log'!E$2:E$201,"LONG")) | G10: =IF(A10="","",SUMIFS('Trade Log'!R$2:R$201,'Trade Log'!B$2:B$201,A10,'Trade Log'!E$2:E$201,"SHORT")) | H10: =IF(A10="","",F10+G10) | I10: =IF(A10="","",I9+H10)
D11: =IF(A11="","",COUNTIFS('Trade Log'!B$2:B$201,A11,'Trade Log'!E$2:E$201,"LONG")) | E11: =IF(A11="","",COUNTIFS('Trade Log'!B$2:B$201,A11,'Trade Log'!E$2:E$201,"SHORT")) | F11: =IF(A11="","",SUMIFS('Trade Log'!R$2:R$201,'Trade Log'!B$2:B$201,A11,'Trade Log'!E$2:E$201,"LONG")) | G11: =IF(A11="","",SUMIFS('Trade Log'!R$2:R$201,'Trade Log'!B$2:B$201,A11,'Trade Log'!E$2:E$201,"SHORT")) | H11: =IF(A11="","",F11+G11) | I11: =IF(A11="","",I10+H11)
D12: =IF(A12="","",COUNTIFS('Trade Log'!B$2:B$201,A12,'Trade Log'!E$2:E$201,"LONG")) | E12: =IF(A12="","",COUNTIFS('Trade Log'!B$2:B$201,A12,'Trade Log'!E$2:E$201,"SHORT")) | F12: =IF(A12="","",SUMIFS('Trade Log'!R$2:R$201,'Trade Log'!B$2:B$201,A12,'Trade Log'!E$2:E$201,"LONG")) | G12: =IF(A12="","",SUMIFS('Trade Log'!R$2:R$201,'Trade Log'!B$2:B$201,A12,'Trade Log'!E$2:E$201,"SHORT")) | H12: =IF(A12="","",F12+G12) | I12: =IF(A12="","",I11+H12)
D13: =IF(A13="","",COUNTIFS('Trade Log'!B$2:B$201,A13,'Trade Log'!E$2:E$201,"LONG")) | E13: =IF(A13="","",COUNTIFS('Trade Log'!B$2:B$201,A13,'Trade Log'!E$2:E$201,"SHORT")) | F13: =IF(A13="","",SUMIFS('Trade Log'!R$2:R$201,'Trade Log'!B$2:B$201,A13,'Trade Log'!E$2:E$201,"LONG")) | G13: =IF(A13="","",SUMIFS('Trade Log'!R$2:R$201,'Trade Log'!B$2:B$201,A13,'Trade Log'!E$2:E$201,"SHORT")) | H13: =IF(A13="","",F13+G13) | I13: =IF(A13="","",I12+H13)
D14: =IF(A14="","",COUNTIFS('Trade Log'!B$2:B$201,A14,'Trade Log'!E$2:E$201,"LONG")) | E14: =IF(A14="","",COUNTIFS('Trade Log'!B$2:B$201,A14,'Trade Log'!E$2:E$201,"SHORT")) | F14: =IF(A14="","",SUMIFS('Trade Log'!R$2:R$201,'Trade Log'!B$2:B$201,A14,'Trade Log'!E$2:E$201,"LONG")) | G14: =IF(A14="","",SUMIFS('Trade Log'!R$2:R$201,'Trade Log'!B$2:B$201,A14,'Trade Log'!E$2:E$201,"SHORT")) | H14: =IF(A14="","",F14+G14) | I14: =IF(A14="","",I13+H14)
... D101: =IF(A101="","",COUNTIFS('Trade Log'!B$2:B$201,A101,'Trade Log'!E$2:E$201,"LONG")) | E101: =IF(A101="","",COUNTIFS('Trade Log'!B$2:B$201,A101,'Trade Log'!E$2:E$201,"SHORT")) | F101: =IF(A101="","",SUMIFS('Trade Log'!R$2:R$201,'Trade Log'!B$2:B$201,A101,'Trade Log'!E$2:E$201,"LONG")) | G101: =IF(A101="","",SUMIFS('Trade Log'!R$2:R$201,'Trade Log'!B$2:B$201,A101,'Trade Log'!E$2:E$201,"SHORT")) | H101: =IF(A101="","",F101+G101) | I101: =IF(A101="","",I100+H101)

Sheet Running Stats
A1: PORTFOLIO D — RUNNING STATISTICS (Variant 2)
A3: Backtest Reference (Frozen) | E3: Per-Book Backtest Reference
A4: PF(R) | B4: 2.23 | E4: Long Book
A5: Exp(R) | B5: +0.461R | E5: N | F5: 37
A6: Total R | B6: +31.79R | E6: PF(R) | F6: 1.74
A7: Max DD (R) | B7: 5.29R | E7: Exp(R) | F7: +0.414R
A8: N | B8: 69 | E8: Total R | F8: +15.32R
A9: WR | B9: 59.4%
A10: Stop Rate | B10: 14.5% | E10: Short Book (BDR AM)
E11: N | F11: 32
A12: Live / Paper Stats | E12: PF(R) | F12: 4.23
A13: Total Trades | B13: =COUNTA('Trade Log'!B2:B201)-COUNTBLANK('Trade Log'!B2:B201) | E13: Exp(R) | F13: +0.515R
A14: Wins | B14: =COUNTIF('Trade Log'!R2:R201,">"&0) | E14: Total R | F14: +16.47R
A15: Losses | B15: =COUNTIF('Trade Log'!R2:R201,"<="&0)
A16: Win Rate | B16: =IF(B13>0,B14/B13,"") | E16: Regime Breakdown (Live)
A17: Gross Win (R) | B17: =SUMIFS('Trade Log'!R$2:R$201,'Trade Log'!R$2:R$201,">"&0) | E17: Regime | F17: Trades | G17: R Total
A18: Gross Loss (R) | B18: =SUMIFS('Trade Log'!R$2:R$201,'Trade Log'!R$2:R$201,"<="&0) | E18: GREEN+TREND | F18: =COUNTIFS('Trade Log'!H$2:H$201,"GREEN+TREND",'Trade Log'!B$2:B$201,"<>"&"") | G18: =SUMIFS('Trade Log'!R$2:R$201,'Trade Log'!H$2:H$201,"GREEN+TREND")
A19: PF(R) | B19: =IF(ABS(B18)>0,B17/ABS(B18),"") | E19: GREEN+CHOPPY | F19: =COUNTIFS('Trade Log'!H$2:H$201,"GREEN+CHOPPY",'Trade Log'!B$2:B$201,"<>"&"") | G19: =SUMIFS('Trade Log'!R$2:R$201,'Trade Log'!H$2:H$201,"GREEN+CHOPPY")
A20: Exp(R) | B20: =IF(B13>0,(B17+B18)/B13,"") | E20: RED+TREND | F20: =COUNTIFS('Trade Log'!H$2:H$201,"RED+TREND",'Trade Log'!B$2:B$201,"<>"&"") | G20: =SUMIFS('Trade Log'!R$2:R$201,'Trade Log'!H$2:H$201,"RED+TREND")
A21: Total R | B21: =IF(B13>0,B17+B18,"") | E21: RED+CHOPPY | F21: =COUNTIFS('Trade Log'!H$2:H$201,"RED+CHOPPY",'Trade Log'!B$2:B$201,"<>"&"") | G21: =SUMIFS('Trade Log'!R$2:R$201,'Trade Log'!H$2:H$201,"RED+CHOPPY")
A22: Max DD (R) | B22: =IF(B13>0,MAX(INDIRECT("'Trade Log'!T2:T"&(B13+1)))-MIN(INDIRECT("'Trade Log'!T2:T"&(B13+1))),"") | E22: FLAT+TREND | F22: =COUNTIFS('Trade Log'!H$2:H$201,"FLAT+TREND",'Trade Log'!B$2:B$201,"<>"&"") | G22: =SUMIFS('Trade Log'!R$2:R$201,'Trade Log'!H$2:H$201,"FLAT+TREND")
A23: Stop Rate | B23: =IF(B13>0,COUNTIFS('Trade Log'!O2:O201,"stop")/B13,"") | E23: FLAT+CHOPPY | F23: =COUNTIFS('Trade Log'!H$2:H$201,"FLAT+CHOPPY",'Trade Log'!B$2:B$201,"<>"&"") | G23: =SUMIFS('Trade Log'!R$2:R$201,'Trade Log'!H$2:H$201,"FLAT+CHOPPY")
A25: Long Book (Live)
A26: Long Trades | B26: =COUNTIFS('Trade Log'!E$2:E$201,"LONG",'Trade Log'!B$2:B$201,"<>"&"") | E26: Setup Breakdown (Live)
A27: Long WR | B27: =IF(B26>0,COUNTIFS('Trade Log'!E$2:E$201,"LONG",'Trade Log'!R$2:R$201,">"&0)/B26,"") | E27: Setup | F27: Trades | G27: R Total
A28: Long PF(R) | B28: =IF(B26>0,SUMIFS('Trade Log'!R$2:R$201,'Trade Log'!E$2:E$201,"LONG",'Trade Log'!R$2:R$201,">"&0)/ABS(SUMIFS('Trade Log'!R$2:R$201,'Trade Log'!E$2:E$201,"LONG",'Trade Log'!R$2:R$201,"<="&0)),"") | E28: VWAP_KISS | F28: =COUNTIFS('Trade Log'!F$2:F$201,"VWAP_KISS",'Trade Log'!B$2:B$201,"<>"&"") | G28: =SUMIFS('Trade Log'!R$2:R$201,'Trade Log'!F$2:F$201,"VWAP_KISS")
A29: Long Exp(R) | B29: =IF(B26>0,SUMIFS('Trade Log'!R$2:R$201,'Trade Log'!E$2:E$201,"LONG")/B26,"") | E29: SECOND_CHANCE | F29: =COUNTIFS('Trade Log'!F$2:F$201,"SECOND_CHANCE",'Trade Log'!B$2:B$201,"<>"&"") | G29: =SUMIFS('Trade Log'!R$2:R$201,'Trade Log'!F$2:F$201,"SECOND_CHANCE")
A30: Long Total R | B30: =SUMIFS('Trade Log'!R$2:R$201,'Trade Log'!E$2:E$201,"LONG") | E30: SC_V2 | F30: =COUNTIFS('Trade Log'!F$2:F$201,"SC_V2",'Trade Log'!B$2:B$201,"<>"&"") | G30: =SUMIFS('Trade Log'!R$2:R$201,'Trade Log'!F$2:F$201,"SC_V2")
E31: SPENCER | F31: =COUNTIFS('Trade Log'!F$2:F$201,"SPENCER",'Trade Log'!B$2:B$201,"<>"&"") | G31: =SUMIFS('Trade Log'!R$2:R$201,'Trade Log'!F$2:F$201,"SPENCER")
A32: Short Book (Live) | E32: BDR_SHORT | F32: =COUNTIFS('Trade Log'!F$2:F$201,"BDR_SHORT",'Trade Log'!B$2:B$201,"<>"&"") | G32: =SUMIFS('Trade Log'!R$2:R$201,'Trade Log'!F$2:F$201,"BDR_SHORT")
A33: Short Trades | B33: =COUNTIFS('Trade Log'!E$2:E$201,"SHORT",'Trade Log'!B$2:B$201,"<>"&"") | E33: EMA_RECLAIM | F33: =COUNTIFS('Trade Log'!F$2:F$201,"EMA_RECLAIM",'Trade Log'!B$2:B$201,"<>"&"") | G33: =SUMIFS('Trade Log'!R$2:R$201,'Trade Log'!F$2:F$201,"EMA_RECLAIM")
A34: Short WR | B34: =IF(B33>0,COUNTIFS('Trade Log'!E$2:E$201,"SHORT",'Trade Log'!R$2:R$201,">"&0)/B33,"") | E34: EMA_FPIP | F34: =COUNTIFS('Trade Log'!F$2:F$201,"EMA_FPIP",'Trade Log'!B$2:B$201,"<>"&"") | G34: =SUMIFS('Trade Log'!R$2:R$201,'Trade Log'!F$2:F$201,"EMA_FPIP")
A35: Short PF(R) | B35: =IF(B33>0,SUMIFS('Trade Log'!R$2:R$201,'Trade Log'!E$2:E$201,"SHORT",'Trade Log'!R$2:R$201,">"&0)/ABS(SUMIFS('Trade Log'!R$2:R$201,'Trade Log'!E$2:E$201,"SHORT",'Trade Log'!R$2:R$201,"<="&0)),"")
A36: Short Exp(R) | B36: =IF(B33>0,SUMIFS('Trade Log'!R$2:R$201,'Trade Log'!E$2:E$201,"SHORT")/B33,"")
A37: Short Total R | B37: =SUMIFS('Trade Log'!R$2:R$201,'Trade Log'!E$2:E$201,"SHORT")
A39: Promotion Readiness
A40: Min 50 trades | B40: =IF(B13>=50,"PASS","FAIL ("&B13&"/50)")
A41: Min 25 long trades | B41: =IF(B26>=25,"PASS","FAIL ("&B26&"/25)")
A42: Min 15 short trades | B42: =IF(B33>=15,"PASS","FAIL ("&B33&"/15)")
A43: PF(R) >= 1.30 | B43: =IF(B19="","—",IF(B19>=1.3,"PASS","FAIL ("&TEXT(B19,"0.00")&")"))
...
