Workbook

Sheet Instructions
A1: How to Use This Trade Journal
A3: TRADE LOG TAB
B4: Enter each trade in a new row. Fill in columns B through M (Date, Time, Symbol, Direction, Setup, Entry, Stop, Target, Shares, Exit Price, Exit Time, Exit Reason). Columns N through Q auto-calculate P&L, R-Multiple, and Win/Loss.
B5: Direction: Choose LONG or SHORT from the dropdown.
B6: Setup: Choose from your 7 alert types (BOX_REV, MANIP, VWAP_SEP, EMA9_SEP, VWAP_KISS, EMA_PULL, EMA_RETEST).
B7: Exit Reason: Target Hit, Stop Hit, Trailing Stop, Time Exit, Manual, or Partial.
B8: Notes: Write anything useful — what you saw, why you entered, what you learned.
A10: DASHBOARD TAB
B11: All metrics update automatically as you add trades. Win rate, profit factor, expectancy, setup performance, direction breakdown, and time-of-day analysis are all formula-driven.
A13: BEHAVIORAL TAB
B14: Tracks streaks, largest winners/losers, exit reason effectiveness, and per-symbol performance. Use this to spot patterns like: Are you better at longs? Do you overtrade after lunch? Are stop-hit exits your biggest losses?
A16: DAILY P&L TAB
B17: Enter the date in column A for each trading day. All other columns auto-calculate from the Trade Log. Cumulative P&L builds automatically.
A19: TIPS
B20: 1. Be consistent — log EVERY trade, even the bad ones. Especially the bad ones.
B21: 2. Fill in the Hold Time (minutes) to track if you're cutting winners short or holding losers too long.
B22: 3. Use Notes for context you'll forget later: market conditions, news, your emotional state.
B23: 4. Review weekly: which setups are working? Which time blocks? Which symbols?
B24: 5. The R-Multiple column tells you how many units of risk you gained or lost. Anything above 1.0R is a winner that met your target.
A26: NEW COLUMNS (added)
B27: Grade (A/B/C): Rate the quality of the setup before or after the trade. A = perfect alignment, B = acceptable, C = marginal/forced. The Dashboard shows P&L by grade.
B28: Rules? (Y/N): Did you follow your trading plan? Entry, stop, target, size all as planned? The Dashboard compares rule-following vs. rule-breaking P&L.
B29: Emotion: Your state when you took the trade. Calm, Focused, Hesitant, Frustrated, FOMO, Revenge, Tired, Distracted. Correlations with P&L are often stark.
B30: Mistake: If something went wrong, tag it. None, Chased Entry, Early Exit, Late Exit, No Stop, Moved Stop, Oversized, Forced Trade, etc. The Dashboard shows total cost of each mistake type.
B31: Regime: Market day type. Trend, Rotation, Choppy, High Vol, Low Vol. Your engine already classifies this. Shows which setups work in which conditions.
B32: Fees: Total commissions + fees for the trade. Net P&L auto-calculates as Gross P&L minus Fees.
B33: MAE: Maximum Adverse Excursion. How far did the trade go against you (in dollars per share) before the outcome? Helps answer: are my stops too tight?
B34: MFE: Maximum Favorable Excursion. How far did the trade go in your favor (in dollars per share) before you exited? Helps answer: am I leaving money on the table?

Sheet Trade Log
A1: Trade # | B1: Date | C1: Time | D1: Symbol | E1: Direction | F1: Setup | G1: Entry Price | H1: Stop Price | I1: Target Price | J1: Shares | K1: Exit Price | L1: Exit Time | M1: Exit Reason | N1: P&L ($) | O1: P&L (%) | P1: R-Multiple | Q1: Win/Loss | R1: Held (min) | S1: Notes | T1: Screenshot Link | U1: Grade | V1: Rules? | W1: Emotion | X1: Mistake | Y1: Regime | Z1: Fees | AA1: MAE | AB1: MFE | AC1: Net P&L
A2: 1 | B2: 2026-03-06 | C2: 0.63378472 | D2: TSLA | E2: LONG | G2: 396 | J2: 20 | K2: 397.14 | L2: 0.65512731 | N2: 22.8 | O2: 0.002879 | P2: =IF(OR(H2="",H2=0),"",N2/(ABS(G2-H2)*J2)) | Q2: WIN | R2: 30 | AC2: =IF(N2="","",N2-IF(Z2="",0,Z2))
A3: 2 | B3: 2026-03-06 | C3: 0.66119213 | D3: TSLA | E3: LONG | G3: 397.47 | J3: 20 | K3: 397.49 | L3: 0.66364583 | N3: 0.4 | O3: 5e-05 | P3: =IF(OR(H3="",H3=0),"",N3/(ABS(G3-H3)*J3)) | Q3: WIN | R3: 3 | AC3: =IF(N3="","",N3-IF(Z3="",0,Z3))
A4: 3 | B4: 2026-03-06 | C4: 0.66622685 | D4: TSLA | E4: LONG | G4: 397.17 | J4: 20 | K4: 398.96 | L4: 0.68135417 | N4: 35.8 | O4: 0.004507 | P4: =IF(OR(H4="",H4=0),"",N4/(ABS(G4-H4)*J4)) | Q4: WIN | R4: 21 | AC4: =IF(N4="","",N4-IF(Z4="",0,Z4))
A5: 4 | B5: 2026-03-06 | C5: 0.76141204 | D5: SOXL | E5: LONG | G5: 51.85 | J5: 100 | K5: 52.21 | L5: 0.77497685 | N5: 36 | O5: 0.006943 | P5: =IF(OR(H5="",H5=0),"",N5/(ABS(G5-H5)*J5)) | Q5: WIN | R5: 19 | AC5: =IF(N5="","",N5-IF(Z5="",0,Z5))
A6: 5 | B6: 2026-03-06 | C6: 0.7797338 | D6: SOXL | E6: LONG | G6: 51.81 | J6: 100 | K6: 51.76 | L6: 0.78814815 | N6: -5 | O6: -0.000965 | P6: =IF(OR(H6="",H6=0),"",N6/(ABS(G6-H6)*J6)) | Q6: LOSS | R6: 12 | AC6: =IF(N6="","",N6-IF(Z6="",0,Z6))
A14: =IF(B14="","",ROW()-1) | N14: =IF(OR(K14="",G14="",J14=""),"",IF(E14="LONG",(K14-G14)*J14,(G14-K14)*J14)) | O14: =IF(OR(K14="",G14="",G14=0),"",IF(E14="LONG",(K14-G14)/G14,(G14-K14)/G14)) | P14: =IF(OR(N14="",H14="",G14="",ABS(G14-H14)=0),"",N14/(ABS(G14-H14)*J14)) | Q14: =IF(N14="","",IF(N14>0,"WIN",IF(N14<0,"LOSS","FLAT"))) | AC14: =IF(N14="","",N14-IF(Z14="",0,Z14))
A15: =IF(B15="","",ROW()-1) | N15: =IF(OR(K15="",G15="",J15=""),"",IF(E15="LONG",(K15-G15)*J15,(G15-K15)*J15)) | O15: =IF(OR(K15="",G15="",G15=0),"",IF(E15="LONG",(K15-G15)/G15,(G15-K15)/G15)) | P15: =IF(OR(N15="",H15="",G15="",ABS(G15-H15)=0),"",N15/(ABS(G15-H15)*J15)) | Q15: =IF(N15="","",IF(N15>0,"WIN",IF(N15<0,"LOSS","FLAT"))) | AC15: =IF(N15="","",N15-IF(Z15="",0,Z15))
A16: =IF(B16="","",ROW()-1) | N16: =IF(OR(K16="",G16="",J16=""),"",IF(E16="LONG",(K16-G16)*J16,(G16-K16)*J16)) | O16: =IF(OR(K16="",G16="",G16=0),"",IF(E16="LONG",(K16-G16)/G16,(G16-K16)/G16)) | P16: =IF(OR(N16="",H16="",G16="",ABS(G16-H16)=0),"",N16/(ABS(G16-H16)*J16)) | Q16: =IF(N16="","",IF(N16>0,"WIN",IF(N16<0,"LOSS","FLAT"))) | AC16: =IF(N16="","",N16-IF(Z16="",0,Z16))
A17: =IF(B17="","",ROW()-1) | N17: =IF(OR(K17="",G17="",J17=""),"",IF(E17="LONG",(K17-G17)*J17,(G17-K17)*J17)) | O17: =IF(OR(K17="",G17="",G17=0),"",IF(E17="LONG",(K17-G17)/G17,(G17-K17)/G17)) | P17: =IF(OR(N17="",H17="",G17="",ABS(G17-H17)=0),"",N17/(ABS(G17-H17)*J17)) | Q17: =IF(N17="","",IF(N17>0,"WIN",IF(N17<0,"LOSS","FLAT"))) | AC17: =IF(N17="","",N17-IF(Z17="",0,Z17))
A18: =IF(B18="","",ROW()-1) | N18: =IF(OR(K18="",G18="",J18=""),"",IF(E18="LONG",(K18-G18)*J18,(G18-K18)*J18)) | O18: =IF(OR(K18="",G18="",G18=0),"",IF(E18="LONG",(K18-G18)/G18,(G18-K18)/G18)) | P18: =IF(OR(N18="",H18="",G18="",ABS(G18-H18)=0),"",N18/(ABS(G18-H18)*J18)) | Q18: =IF(N18="","",IF(N18>0,"WIN",IF(N18<0,"LOSS","FLAT"))) | AC18: =IF(N18="","",N18-IF(Z18="",0,Z18))
A19: =IF(B19="","",ROW()-1) | N19: =IF(OR(K19="",G19="",J19=""),"",IF(E19="LONG",(K19-G19)*J19,(G19-K19)*J19)) | O19: =IF(OR(K19="",G19="",G19=0),"",IF(E19="LONG",(K19-G19)/G19,(G19-K19)/G19)) | P19: =IF(OR(N19="",H19="",G19="",ABS(G19-H19)=0),"",N19/(ABS(G19-H19)*J19)) | Q19: =IF(N19="","",IF(N19>0,"WIN",IF(N19<0,"LOSS","FLAT"))) | AC19: =IF(N19="","",N19-IF(Z19="",0,Z19))
A20: =IF(B20="","",ROW()-1) | N20: =IF(OR(K20="",G20="",J20=""),"",IF(E20="LONG",(K20-G20)*J20,(G20-K20)*J20)) | O20: =IF(OR(K20="",G20="",G20=0),"",IF(E20="LONG",(K20-G20)/G20,(G20-K20)/G20)) | P20: =IF(OR(N20="",H20="",G20="",ABS(G20-H20)=0),"",N20/(ABS(G20-H20)*J20)) | Q20: =IF(N20="","",IF(N20>0,"WIN",IF(N20<0,"LOSS","FLAT"))) | AC20: =IF(N20="","",N20-IF(Z20="",0,Z20))
A21: =IF(B21="","",ROW()-1) | N21: =IF(OR(K21="",G21="",J21=""),"",IF(E21="LONG",(K21-G21)*J21,(G21-K21)*J21)) | O21: =IF(OR(K21="",G21="",G21=0),"",IF(E21="LONG",(K21-G21)/G21,(G21-K21)/G21)) | P21: =IF(OR(N21="",H21="",G21="",ABS(G21-H21)=0),"",N21/(ABS(G21-H21)*J21)) | Q21: =IF(N21="","",IF(N21>0,"WIN",IF(N21<0,"LOSS","FLAT"))) | AC21: =IF(N21="","",N21-IF(Z21="",0,Z21))
A22: =IF(B22="","",ROW()-1) | N22: =IF(OR(K22="",G22="",J22=""),"",IF(E22="LONG",(K22-G22)*J22,(G22-K22)*J22)) | O22: =IF(OR(K22="",G22="",G22=0),"",IF(E22="LONG",(K22-G22)/G22,(G22-K22)/G22)) | P22: =IF(OR(N22="",H22="",G22="",ABS(G22-H22)=0),"",N22/(ABS(G22-H22)*J22)) | Q22: =IF(N22="","",IF(N22>0,"WIN",IF(N22<0,"LOSS","FLAT"))) | AC22: =IF(N22="","",N22-IF(Z22="",0,Z22))
A23: =IF(B23="","",ROW()-1) | N23: =IF(OR(K23="",G23="",J23=""),"",IF(E23="LONG",(K23-G23)*J23,(G23-K23)*J23)) | O23: =IF(OR(K23="",G23="",G23=0),"",IF(E23="LONG",(K23-G23)/G23,(G23-K23)/G23)) | P23: =IF(OR(N23="",H23="",G23="",ABS(G23-H23)=0),"",N23/(ABS(G23-H23)*J23)) | Q23: =IF(N23="","",IF(N23>0,"WIN",IF(N23<0,"LOSS","FLAT"))) | AC23: =IF(N23="","",N23-IF(Z23="",0,Z23))
A24: =IF(B24="","",ROW()-1) | N24: =IF(OR(K24="",G24="",J24=""),"",IF(E24="LONG",(K24-G24)*J24,(G24-K24)*J24)) | O24: =IF(OR(K24="",G24="",G24=0),"",IF(E24="LONG",(K24-G24)/G24,(G24-K24)/G24)) | P24: =IF(OR(N24="",H24="",G24="",ABS(G24-H24)=0),"",N24/(ABS(G24-H24)*J24)) | Q24: =IF(N24="","",IF(N24>0,"WIN",IF(N24<0,"LOSS","FLAT"))) | AC24: =IF(N24="","",N24-IF(Z24="",0,Z24))
A25: =IF(B25="","",ROW()-1) | N25: =IF(OR(K25="",G25="",J25=""),"",IF(E25="LONG",(K25-G25)*J25,(G25-K25)*J25)) | O25: =IF(OR(K25="",G25="",G25=0),"",IF(E25="LONG",(K25-G25)/G25,(G25-K25)/G25)) | P25: =IF(OR(N25="",H25="",G25="",ABS(G25-H25)=0),"",N25/(ABS(G25-H25)*J25)) | Q25: =IF(N25="","",IF(N25>0,"WIN",IF(N25<0,"LOSS","FLAT"))) | AC25: =IF(N25="","",N25-IF(Z25="",0,Z25))
... A500: =IF(B500="","",ROW()-1) | N500: =IF(OR(K500="",G500="",J500=""),"",IF(E500="LONG",(K500-G500)*J500,(G500-K500)*J500)) | O500: =IF(OR(K500="",G500="",G500=0),"",IF(E500="LONG",(K500-G500)/G500,(G500-K500)/G500)) | P500: =IF(OR(N500="",H500="",G500="",ABS(G500-H500)=0),"",N500/(ABS(G500-H500)*J500)) | Q500: =IF(N500="","",IF(N500>0,"WIN",IF(N500<0,"LOSS","FLAT"))) | AC500: =IF(N500="","",N500-IF(Z500="",0,Z500))

Sheet Dashboard
A1: Trading Performance Dashboard
B2: Total Trades | C2: Win Rate | D2: Total P&L | E2: Avg Winner ($) | F2: Avg Loser ($) | G2: Profit Factor | H2: Avg R-Multiple | I2: Expectancy/Trade | J2: Net P&L | K2: Total Fees
B3: =COUNTIF('Trade Log'!Q2:Q1000,"WIN")+COUNTIF('Trade Log'!Q2:Q1000,"LOSS")+COUNTIF('Trade Log'!Q2:Q1000,"FLAT") | C3: =IF(B3=0,"-",COUNTIF('Trade Log'!Q2:Q1000,"WIN")/(COUNTIF('Trade Log'!Q2:Q1000,"WIN")+COUNTIF('Trade Log'!Q2:Q1000,"LOSS")+COUNTIF('Trade Log'!Q2:Q1000,"FLAT"))) | D3: =SUMIF('Trade Log'!N2:N500,">0")+SUMIF('Trade Log'!N2:N500,"<0") | E3: =IF(COUNTIF('Trade Log'!Q2:Q1000,"WIN")=0,"-",AVERAGEIF('Trade Log'!Q2:Q1000,"WIN",'Trade Log'!N2:N1000)) | F3: =IF(COUNTIF('Trade Log'!Q2:Q1000,"LOSS")=0,"-",AVERAGEIF('Trade Log'!Q2:Q1000,"LOSS",'Trade Log'!N2:N1000)) | G3: =IF(SUMIF('Trade Log'!N2:N500,"<0")=0,"-",SUMIF('Trade Log'!N2:N500,">0")/ABS(SUMIF('Trade Log'!N2:N500,"<0"))) | H3: =IFERROR(IF(COUNTA('Trade Log'!R2:P1000)=0,"-",AVERAGE('Trade Log'!R2:P1000)),"-") | I3: =IF(B3=0,"-",D3/B3) | J3: =SUMIF('Trade Log'!AC2:AC500,">0")+SUMIF('Trade Log'!AC2:AC500,"<0") | K3: =SUMIF('Trade Log'!Z2:Z500,">0")
B5: Performance by Setup
B6: Setup | C6: Trades | D6: Wins | E6: Win Rate | F6: Avg P&L | G6: Total P&L | H6: Avg R | I6: Losses | J6: % of Trades
B7: BOX_REV | C7: =COUNTIF('Trade Log'!F:F,"BOX_REV") | D7: =COUNTIFS('Trade Log'!F:F,"BOX_REV",'Trade Log'!Q:Q,"WIN") | E7: =IF(C7=0,"-",D7/C7) | F7: =IF(C7=0,"-",AVERAGEIF('Trade Log'!F:F,"BOX_REV",'Trade Log'!N:N)) | G7: =IF(C7=0,"-",SUMIF('Trade Log'!F:F,"BOX_REV",'Trade Log'!N:N)) | H7: =IF(C7=0,"-",AVERAGEIF('Trade Log'!F:F,"BOX_REV",'Trade Log'!R:P)) | I7: =IF(C7=0,"-",C7-D7) | J7: =IF($B$3=0,"-",C7/$B$3)
B8: MANIP | C8: =COUNTIF('Trade Log'!F:F,"MANIP") | D8: =COUNTIFS('Trade Log'!F:F,"MANIP",'Trade Log'!Q:Q,"WIN") | E8: =IF(C8=0,"-",D8/C8) | F8: =IF(C8=0,"-",AVERAGEIF('Trade Log'!F:F,"MANIP",'Trade Log'!N:N)) | G8: =IF(C8=0,"-",SUMIF('Trade Log'!F:F,"MANIP",'Trade Log'!N:N)) | H8: =IF(C8=0,"-",AVERAGEIF('Trade Log'!F:F,"MANIP",'Trade Log'!R:P)) | I8: =IF(C8=0,"-",C8-D8) | J8: =IF($B$3=0,"-",C8/$B$3)
B9: VWAP_SEP | C9: =COUNTIF('Trade Log'!F:F,"VWAP_SEP") | D9: =COUNTIFS('Trade Log'!F:F,"VWAP_SEP",'Trade Log'!Q:Q,"WIN") | E9: =IF(C9=0,"-",D9/C9) | F9: =IF(C9=0,"-",AVERAGEIF('Trade Log'!F:F,"VWAP_SEP",'Trade Log'!N:N)) | G9: =IF(C9=0,"-",SUMIF('Trade Log'!F:F,"VWAP_SEP",'Trade Log'!N:N)) | H9: =IF(C9=0,"-",AVERAGEIF('Trade Log'!F:F,"VWAP_SEP",'Trade Log'!R:P)) | I9: =IF(C9=0,"-",C9-D9) | J9: =IF($B$3=0,"-",C9/$B$3)
B10: EMA9_SEP | C10: =COUNTIF('Trade Log'!F:F,"EMA9_SEP") | D10: =COUNTIFS('Trade Log'!F:F,"EMA9_SEP",'Trade Log'!Q:Q,"WIN") | E10: =IF(C10=0,"-",D10/C10) | F10: =IF(C10=0,"-",AVERAGEIF('Trade Log'!F:F,"EMA9_SEP",'Trade Log'!N:N)) | G10: =IF(C10=0,"-",SUMIF('Trade Log'!F:F,"EMA9_SEP",'Trade Log'!N:N)) | H10: =IF(C10=0,"-",AVERAGEIF('Trade Log'!F:F,"EMA9_SEP",'Trade Log'!R:P)) | I10: =IF(C10=0,"-",C10-D10) | J10: =IF($B$3=0,"-",C10/$B$3)
B11: VWAP_KISS | C11: =COUNTIF('Trade Log'!F:F,"VWAP_KISS") | D11: =COUNTIFS('Trade Log'!F:F,"VWAP_KISS",'Trade Log'!Q:Q,"WIN") | E11: =IF(C11=0,"-",D11/C11) | F11: =IF(C11=0,"-",AVERAGEIF('Trade Log'!F:F,"VWAP_KISS",'Trade Log'!N:N)) | G11: =IF(C11=0,"-",SUMIF('Trade Log'!F:F,"VWAP_KISS",'Trade Log'!N:N)) | H11: =IF(C11=0,"-",AVERAGEIF('Trade Log'!F:F,"VWAP_KISS",'Trade Log'!R:P)) | I11: =IF(C11=0,"-",C11-D11) | J11: =IF($B$3=0,"-",C11/$B$3)
B12: EMA_PULL | C12: =COUNTIF('Trade Log'!F:F,"EMA_PULL") | D12: =COUNTIFS('Trade Log'!F:F,"EMA_PULL",'Trade Log'!Q:Q,"WIN") | E12: =IF(C12=0,"-",D12/C12) | F12: =IF(C12=0,"-",AVERAGEIF('Trade Log'!F:F,"EMA_PULL",'Trade Log'!N:N)) | G12: =IF(C12=0,"-",SUMIF('Trade Log'!F:F,"EMA_PULL",'Trade Log'!N:N)) | H12: =IF(C12=0,"-",AVERAGEIF('Trade Log'!F:F,"EMA_PULL",'Trade Log'!R:P)) | I12: =IF(C12=0,"-",C12-D12) | J12: =IF($B$3=0,"-",C12/$B$3)
B13: EMA_RETEST | C13: =COUNTIF('Trade Log'!F:F,"EMA_RETEST") | D13: =COUNTIFS('Trade Log'!F:F,"EMA_RETEST",'Trade Log'!Q:Q,"WIN") | E13: =IF(C13=0,"-",D13/C13) | F13: =IF(C13=0,"-",AVERAGEIF('Trade Log'!F:F,"EMA_RETEST",'Trade Log'!N:N)) | G13: =IF(C13=0,"-",SUMIF('Trade Log'!F:F,"EMA_RETEST",'Trade Log'!N:N)) | H13: =IF(C13=0,"-",AVERAGEIF('Trade Log'!F:F,"EMA_RETEST",'Trade Log'!R:P)) | I13: =IF(C13=0,"-",C13-D13) | J13: =IF($B$3=0,"-",C13/$B$3)
B16: Performance by Direction
B17: Direction | C17: Trades | D17: Wins | E17: Win Rate | F17: Avg P&L | G17: Total P&L | H17: Avg R
B18: LONG | C18: =COUNTIF('Trade Log'!E:E,"LONG") | D18: =COUNTIFS('Trade Log'!E:E,"LONG",'Trade Log'!Q:Q,"WIN") | E18: =IF(C18=0,"-",D18/C18) | F18: =IF(C18=0,"-",AVERAGEIF('Trade Log'!E:E,"LONG",'Trade Log'!N:N)) | G18: =IF(C18=0,"-",SUMIF('Trade Log'!E:E,"LONG",'Trade Log'!N:N)) | H18: =IFERROR(IF(C18=0,"-",AVERAGEIF('Trade Log'!E:E,"LONG",'Trade Log'!R:P)),"-")
B19: SHORT | C19: =COUNTIF('Trade Log'!E:E,"SHORT") | D19: =COUNTIFS('Trade Log'!E:E,"SHORT",'Trade Log'!Q:Q,"WIN") | E19: =IF(C19=0,"-",D19/C19) | F19: =IF(C19=0,"-",AVERAGEIF('Trade Log'!E:E,"SHORT",'Trade Log'!N:N)) | G19: =IF(C19=0,"-",SUMIF('Trade Log'!E:E,"SHORT",'Trade Log'!N:N)) | H19: =IFERROR(IF(C19=0,"-",AVERAGEIF('Trade Log'!E:E,"SHORT",'Trade Log'!R:P)),"-")
B22: Performance by Time of Day
B23: Time Block | C23: Trades | D23: Wins | E23: Win Rate | F23: Avg P&L | G23: Total P&L
B24: 9:30-10:00 (Open) | C24: =COUNTIFS('Trade Log'!C:C,">="&TIME(9,30,0),'Trade Log'!C:C,"<"&TIME(10,0,0)) | D24: =COUNTIFS('Trade Log'!C:C,">="&TIME(9,30,0),'Trade Log'!C:C,"<"&TIME(10,0,0),'Trade Log'!Q:Q,"WIN") | E24: =IF(C24=0,"-",D24/C24) | F24: =IF(C24=0,"-",AVERAGEIFS('Trade Log'!N:N,'Trade Log'!C:C,">="&TIME(9,30,0),'Trade Log'!C:C,"<"&TIME(10,0,0))) | G24: =IF(C24=0,"-",SUMIFS('Trade Log'!N:N,'Trade Log'!C:C,">="&TIME(9,30,0),'Trade Log'!C:C,"<"&TIME(10,0,0)))
B25: 10:00-10:45 (Morning) | C25: =COUNTIFS('Trade Log'!C:C,">="&TIME(10,0,0),'Trade Log'!C:C,"<"&TIME(10,45,0)) | D25: =COUNTIFS('Trade Log'!C:C,">="&TIME(10,0,0),'Trade Log'!C:C,"<"&TIME(10,45,0),'Trade Log'!Q:Q,"WIN") | E25: =IF(C25=0,"-",D25/C25) | F25: =IF(C25=0,"-",AVERAGEIFS('Trade Log'!N:N,'Trade Log'!C:C,">="&TIME(10,0,0),'Trade Log'!C:C,"<"&TIME(10,45,0))) | G25: =IF(C25=0,"-",SUMIFS('Trade Log'!N:N,'Trade Log'!C:C,">="&TIME(10,0,0),'Trade Log'!C:C,"<"&TIME(10,45,0)))
B26: 10:45-12:00 (Mid-AM) | C26: =COUNTIFS('Trade Log'!C:C,">="&TIME(10,45,0),'Trade Log'!C:C,"<"&TIME(12,0,0)) | D26: =COUNTIFS('Trade Log'!C:C,">="&TIME(10,45,0),'Trade Log'!C:C,"<"&TIME(12,0,0),'Trade Log'!Q:Q,"WIN") | E26: =IF(C26=0,"-",D26/C26) | F26: =IF(C26=0,"-",AVERAGEIFS('Trade Log'!N:N,'Trade Log'!C:C,">="&TIME(10,45,0),'Trade Log'!C:C,"<"&TIME(12,0,0))) | G26: =IF(C26=0,"-",SUMIFS('Trade Log'!N:N,'Trade Log'!C:C,">="&TIME(10,45,0),'Trade Log'!C:C,"<"&TIME(12,0,0)))
B27: 12:00-1:30 (Lunch) | C27: =COUNTIFS('Trade Log'!C:C,">="&TIME(12,0,0),'Trade Log'!C:C,"<"&TIME(13,30,0)) | D27: =COUNTIFS('Trade Log'!C:C,">="&TIME(12,0,0),'Trade Log'!C:C,"<"&TIME(13,30,0),'Trade Log'!Q:Q,"WIN") | E27: =IF(C27=0,"-",D27/C27) | F27: =IF(C27=0,"-",AVERAGEIFS('Trade Log'!N:N,'Trade Log'!C:C,">="&TIME(12,0,0),'Trade Log'!C:C,"<"&TIME(13,30,0))) | G27: =IF(C27=0,"-",SUMIFS('Trade Log'!N:N,'Trade Log'!C:C,">="&TIME(12,0,0),'Trade Log'!C:C,"<"&TIME(13,30,0)))
B28: 1:30-3:00 (Afternoon) | C28: =COUNTIFS('Trade Log'!C:C,">="&TIME(13,30,0),'Trade Log'!C:C,"<"&TIME(15,0,0)) | D28: =COUNTIFS('Trade Log'!C:C,">="&TIME(13,30,0),'Trade Log'!C:C,"<"&TIME(15,0,0),'Trade Log'!Q:Q,"WIN") | E28: =IF(C28=0,"-",D28/C28) | F28: =IF(C28=0,"-",AVERAGEIFS('Trade Log'!N:N,'Trade Log'!C:C,">="&TIME(13,30,0),'Trade Log'!C:C,"<"&TIME(15,0,0))) | G28: =IF(C28=0,"-",SUMIFS('Trade Log'!N:N,'Trade Log'!C:C,">="&TIME(13,30,0),'Trade Log'!C:C,"<"&TIME(15,0,0)))
B29: 3:00-4:00 (Close) | C29: =COUNTIFS('Trade Log'!C:C,">="&TIME(15,0,0),'Trade Log'!C:C,"<"&TIME(16,0,0)) | D29: =COUNTIFS('Trade Log'!C:C,">="&TIME(15,0,0),'Trade Log'!C:C,"<"&TIME(16,0,0),'Trade Log'!Q:Q,"WIN") | E29: =IF(C29=0,"-",D29/C29) | F29: =IF(C29=0,"-",AVERAGEIFS('Trade Log'!N:N,'Trade Log'!C:C,">="&TIME(15,0,0),'Trade Log'!C:C,"<"&TIME(16,0,0))) | G29: =IF(C29=0,"-",SUMIFS('Trade Log'!N:N,'Trade Log'!C:C,">="&TIME(15,0,0),'Trade Log'!C:C,"<"&TIME(16,0,0)))
B32: Performance by Setup Grade
B33: Grade | C33: Trades | D33: Wins | E33: Win Rate | F33: Avg P&L | G33: Total P&L | H33: Avg R | I33: % of Trades
B34: A | C34: =COUNTIF('Trade Log'!U:U,"A") | D34: =COUNTIFS('Trade Log'!U:U,"A",'Trade Log'!Q:Q,"WIN") | E34: =IF(C34=0,"-",D34/C34) | F34: =IF(C34=0,"-",AVERAGEIF('Trade Log'!U:U,"A",'Trade Log'!N:N)) | G34: =IF(C34=0,"-",SUMIF('Trade Log'!U:U,"A",'Trade Log'!N:N)) | H34: =IF(C34=0,"-",AVERAGEIF('Trade Log'!U:U,"A",'Trade Log'!R:P)) | I34: =IF($B$3=0,"-",C34/$B$3)
B35: B | C35: =COUNTIF('Trade Log'!U:U,"B") | D35: =COUNTIFS('Trade Log'!U:U,"B",'Trade Log'!Q:Q,"WIN") | E35: =IF(C35=0,"-",D35/C35) | F35: =IF(C35=0,"-",AVERAGEIF('Trade Log'!U:U,"B",'Trade Log'!N:N)) | G35: =IF(C35=0,"-",SUMIF('Trade Log'!U:U,"B",'Trade Log'!N:N)) | H35: =IF(C35=0,"-",AVERAGEIF('Trade Log'!U:U,"B",'Trade Log'!R:P)) | I35: =IF($B$3=0,"-",C35/$B$3)
B36: C | C36: =COUNTIF('Trade Log'!U:U,"C") | D36: =COUNTIFS('Trade Log'!U:U,"C",'Trade Log'!Q:Q,"WIN") | E36: =IF(C36=0,"-",D36/C36) | F36: =IF(C36=0,"-",AVERAGEIF('Trade Log'!U:U,"C",'Trade Log'!N:N)) | G36: =IF(C36=0,"-",SUMIF('Trade Log'!U:U,"C",'Trade Log'!N:N)) | H36: =IF(C36=0,"-",AVERAGEIF('Trade Log'!U:U,"C",'Trade Log'!R:P)) | I36: =IF($B$3=0,"-",C36/$B$3)
B38: Rule Adherence Impact
B39: Rules Followed? | C39: Trades | D39: Wins | E39: Win Rate | F39: Avg P&L | G39: Total P&L | H39: Avg R
B40: Yes (followed plan) | C40: =COUNTIF('Trade Log'!V:V,"Y") | D40: =COUNTIFS('Trade Log'!V:V,"Y",'Trade Log'!Q:Q,"WIN") | E40: =IF(C40=0,"-",D40/C40) | F40: =IF(C40=0,"-",AVERAGEIF('Trade Log'!V:V,"Y",'Trade Log'!N:N)) | G40: =IF(C40=0,"-",SUMIF('Trade Log'!V:V,"Y",'Trade Log'!N:N)) | H40: =IF(C40=0,"-",AVERAGEIF('Trade Log'!V:V,"Y",'Trade Log'!R:P))
B41: No (broke rules) | C41: =COUNTIF('Trade Log'!V:V,"N") | D41: =COUNTIFS('Trade Log'!V:V,"N",'Trade Log'!Q:Q,"WIN") | E41: =IF(C41=0,"-",D41/C41) | F41: =IF(C41=0,"-",AVERAGEIF('Trade Log'!V:V,"N",'Trade Log'!N:N)) | G41: =IF(C41=0,"-",SUMIF('Trade Log'!V:V,"N",'Trade Log'!N:N)) | H41: =IF(C41=0,"-",AVERAGEIF('Trade Log'!V:V,"N",'Trade Log'!R:P))
B42: Behavioral Drag (cost of breaking rules): | F42: =IF(COUNTIF('Trade Log'!V:V,"N")=0,"-",SUMIF('Trade Log'!V:V,"N",'Trade Log'!N:N))
B45: Performance by Emotional State
B46: State | C46: Trades | D46: Wins | E46: Win Rate | F46: Avg P&L | G46: Total P&L
B47: Calm | C47: =COUNTIF('Trade Log'!W:W,"Calm") | D47: =COUNTIFS('Trade Log'!W:W,"Calm",'Trade Log'!Q:Q,"WIN") | E47: =IF(C47=0,"-",D47/C47) | F47: =IF(C47=0,"-",AVERAGEIF('Trade Log'!W:W,"Calm",'Trade Log'!N:N)) | G47: =IF(C47=0,"-",SUMIF('Trade Log'!W:W,"Calm",'Trade Log'!N:N))
B48: Focused | C48: =COUNTIF('Trade Log'!W:W,"Focused") | D48: =COUNTIFS('Trade Log'!W:W,"Focused",'Trade Log'!Q:Q,"WIN") | E48: =IF(C48=0,"-",D48/C48) | F48: =IF(C48=0,"-",AVERAGEIF('Trade Log'!W:W,"Focused",'Trade Log'!N:N)) | G48: =IF(C48=0,"-",SUMIF('Trade Log'!W:W,"Focused",'Trade Log'!N:N))
B49: Hesitant | C49: =COUNTIF('Trade Log'!W:W,"Hesitant") | D49: =COUNTIFS('Trade Log'!W:W,"Hesitant",'Trade Log'!Q:Q,"WIN") | E49: =IF(C49=0,"-",D49/C49) | F49: =IF(C49=0,"-",AVERAGEIF('Trade Log'!W:W,"Hesitant",'Trade Log'!N:N)) | G49: =IF(C49=0,"-",SUMIF('Trade Log'!W:W,"Hesitant",'Trade Log'!N:N))
B50: Frustrated | C50: =COUNTIF('Trade Log'!W:W,"Frustrated") | D50: =COUNTIFS('Trade Log'!W:W,"Frustrated",'Trade Log'!Q:Q,"WIN") | E50: =IF(C50=0,"-",D50/C50) | F50: =IF(C50=0,"-",AVERAGEIF('Trade Log'!W:W,"Frustrated",'Trade Log'!N:N)) | G50: =IF(C50=0,"-",SUMIF('Trade Log'!W:W,"Frustrated",'Trade Log'!N:N))
...

Sheet Behavioral
A1: Behavioral Analysis
B3: Streaks & Risk Metrics
B4: Current Streak | C4: =IF(COUNTA('Trade Log'!Q2:Q1000)=0,"-",IF(INDEX('Trade Log'!Q2:Q1000,COUNTA('Trade Log'!Q2:Q1000))="WIN","W","L"))
B5: Max Win Streak | C5: =IF(COUNTA('Trade Log'!Q2:Q1000)=0,"-","See daily log")
B6: Max Loss Streak | C6: =IF(COUNTA('Trade Log'!Q2:Q1000)=0,"-","See daily log")
B7: Largest Winner ($) | C7: =IF(COUNTA('Trade Log'!N2:N1000)=0,"-",MAX('Trade Log'!N2:N1000))
B8: Largest Loser ($) | C8: =IF(COUNTA('Trade Log'!N2:N1000)=0,"-",MIN('Trade Log'!N2:N1000))
B9: Win/Loss Ratio (size) | C9: =IF(OR(COUNTIF('Trade Log'!Q:Q,"WIN")=0,COUNTIF('Trade Log'!Q:Q,"LOSS")=0),"-",ABS(AVERAGEIF('Trade Log'!Q:Q,"WIN",'Trade Log'!N:N)/AVERAGEIF('Trade Log'!Q:Q,"LOSS",'Trade Log'!N:N)))
B10: Avg Hold Time (min) | C10: =IF(COUNTA('Trade Log'!R2:R1000)=0,"-",AVERAGE('Trade Log'!R2:R1000))
B11: Trades per Day (avg) | C11: =IFERROR(IF(COUNTA('Trade Log'!A2:A500)=0,"-",COUNTA('Trade Log'!A2:A500)/MAX(1,SUMPRODUCT(1/COUNTIF('Trade Log'!A2:A500,'Trade Log'!A2:A500)))),"-")
B14: Exit Reason Breakdown
B15: Exit Reason | C15: Count | D15: Win Rate | E15: Avg P&L
B16: Target Hit | C16: =COUNTIF('Trade Log'!M:M,"Target Hit") | D16: =IF(C16=0,"-",COUNTIFS('Trade Log'!M:M,"Target Hit",'Trade Log'!Q:Q,"WIN")/C16) | E16: =IF(C16=0,"-",AVERAGEIF('Trade Log'!M:M,"Target Hit",'Trade Log'!N:N))
B17: Stop Hit | C17: =COUNTIF('Trade Log'!M:M,"Stop Hit") | D17: =IF(C17=0,"-",COUNTIFS('Trade Log'!M:M,"Stop Hit",'Trade Log'!Q:Q,"WIN")/C17) | E17: =IF(C17=0,"-",AVERAGEIF('Trade Log'!M:M,"Stop Hit",'Trade Log'!N:N))
B18: Trailing Stop | C18: =COUNTIF('Trade Log'!M:M,"Trailing Stop") | D18: =IF(C18=0,"-",COUNTIFS('Trade Log'!M:M,"Trailing Stop",'Trade Log'!Q:Q,"WIN")/C18) | E18: =IF(C18=0,"-",AVERAGEIF('Trade Log'!M:M,"Trailing Stop",'Trade Log'!N:N))
B19: Time Exit | C19: =COUNTIF('Trade Log'!M:M,"Time Exit") | D19: =IF(C19=0,"-",COUNTIFS('Trade Log'!M:M,"Time Exit",'Trade Log'!Q:Q,"WIN")/C19) | E19: =IF(C19=0,"-",AVERAGEIF('Trade Log'!M:M,"Time Exit",'Trade Log'!N:N))
B20: Manual | C20: =COUNTIF('Trade Log'!M:M,"Manual") | D20: =IF(C20=0,"-",COUNTIFS('Trade Log'!M:M,"Manual",'Trade Log'!Q:Q,"WIN")/C20) | E20: =IF(C20=0,"-",AVERAGEIF('Trade Log'!M:M,"Manual",'Trade Log'!N:N))
B21: Partial | C21: =COUNTIF('Trade Log'!M:M,"Partial") | D21: =IF(C21=0,"-",COUNTIFS('Trade Log'!M:M,"Partial",'Trade Log'!Q:Q,"WIN")/C21) | E21: =IF(C21=0,"-",AVERAGEIF('Trade Log'!M:M,"Partial",'Trade Log'!N:N))
B24: Top Symbols by Trade Count
B25: Symbol | C25: Trades | D25: Wins | E25: Win Rate | F25: Total P&L | G25: Avg R
B26: TSLA | C26: =COUNTIF('Trade Log'!D:D,"TSLA") | D26: =COUNTIFS('Trade Log'!D:D,"TSLA",'Trade Log'!Q:Q,"WIN") | E26: =IF(C26=0,"-",D26/C26) | F26: =IF(C26=0,"-",SUMIF('Trade Log'!D:D,"TSLA",'Trade Log'!N:N)) | G26: =IFERROR(IF(C26=0,"-",AVERAGEIF('Trade Log'!D:D,"TSLA",'Trade Log'!R:P)),"-")
B27: AAPL | C27: =COUNTIF('Trade Log'!D:D,"AAPL") | D27: =COUNTIFS('Trade Log'!D:D,"AAPL",'Trade Log'!Q:Q,"WIN") | E27: =IF(C27=0,"-",D27/C27) | F27: =IF(C27=0,"-",SUMIF('Trade Log'!D:D,"AAPL",'Trade Log'!N:N)) | G27: =IF(C27=0,"-",AVERAGEIF('Trade Log'!D:D,"AAPL",'Trade Log'!R:P))
B28: NVDA | C28: =COUNTIF('Trade Log'!D:D,"NVDA") | D28: =COUNTIFS('Trade Log'!D:D,"NVDA",'Trade Log'!Q:Q,"WIN") | E28: =IF(C28=0,"-",D28/C28) | F28: =IF(C28=0,"-",SUMIF('Trade Log'!D:D,"NVDA",'Trade Log'!N:N)) | G28: =IF(C28=0,"-",AVERAGEIF('Trade Log'!D:D,"NVDA",'Trade Log'!R:P))
B29: SPY | C29: =COUNTIF('Trade Log'!D:D,"SPY") | D29: =COUNTIFS('Trade Log'!D:D,"SPY",'Trade Log'!Q:Q,"WIN") | E29: =IF(C29=0,"-",D29/C29) | F29: =IF(C29=0,"-",SUMIF('Trade Log'!D:D,"SPY",'Trade Log'!N:N)) | G29: =IF(C29=0,"-",AVERAGEIF('Trade Log'!D:D,"SPY",'Trade Log'!R:P))
B30: QQQ | C30: =COUNTIF('Trade Log'!D:D,"QQQ") | D30: =COUNTIFS('Trade Log'!D:D,"QQQ",'Trade Log'!Q:Q,"WIN") | E30: =IF(C30=0,"-",D30/C30) | F30: =IF(C30=0,"-",SUMIF('Trade Log'!D:D,"QQQ",'Trade Log'!N:N)) | G30: =IF(C30=0,"-",AVERAGEIF('Trade Log'!D:D,"QQQ",'Trade Log'!R:P))
B31: TQQQ | C31: =COUNTIF('Trade Log'!D:D,"TQQQ") | D31: =COUNTIFS('Trade Log'!D:D,"TQQQ",'Trade Log'!Q:Q,"WIN") | E31: =IF(C31=0,"-",D31/C31) | F31: =IF(C31=0,"-",SUMIF('Trade Log'!D:D,"TQQQ",'Trade Log'!N:N)) | G31: =IF(C31=0,"-",AVERAGEIF('Trade Log'!D:D,"TQQQ",'Trade Log'!R:P))
B32: AMD | C32: =COUNTIF('Trade Log'!D:D,"AMD") | D32: =COUNTIFS('Trade Log'!D:D,"AMD",'Trade Log'!Q:Q,"WIN") | E32: =IF(C32=0,"-",D32/C32) | F32: =IF(C32=0,"-",SUMIF('Trade Log'!D:D,"AMD",'Trade Log'!N:N)) | G32: =IF(C32=0,"-",AVERAGEIF('Trade Log'!D:D,"AMD",'Trade Log'!R:P))
B33: NVDL | C33: =COUNTIF('Trade Log'!D:D,"NVDL") | D33: =COUNTIFS('Trade Log'!D:D,"NVDL",'Trade Log'!Q:Q,"WIN") | E33: =IF(C33=0,"-",D33/C33) | F33: =IF(C33=0,"-",SUMIF('Trade Log'!D:D,"NVDL",'Trade Log'!N:N)) | G33: =IF(C33=0,"-",AVERAGEIF('Trade Log'!D:D,"NVDL",'Trade Log'!R:P))
B34: SPXL | C34: =COUNTIF('Trade Log'!D:D,"SPXL") | D34: =COUNTIFS('Trade Log'!D:D,"SPXL",'Trade Log'!Q:Q,"WIN") | E34: =IF(C34=0,"-",D34/C34) | F34: =IF(C34=0,"-",SUMIF('Trade Log'!D:D,"SPXL",'Trade Log'!N:N)) | G34: =IF(C34=0,"-",AVERAGEIF('Trade Log'!D:D,"SPXL",'Trade Log'!R:P))
B35: META | C35: =COUNTIF('Trade Log'!D:D,"META") | D35: =COUNTIFS('Trade Log'!D:D,"META",'Trade Log'!Q:Q,"WIN") | E35: =IF(C35=0,"-",D35/C35) | F35: =IF(C35=0,"-",SUMIF('Trade Log'!D:D,"META",'Trade Log'!N:N)) | G35: =IF(C35=0,"-",AVERAGEIF('Trade Log'!D:D,"META",'Trade Log'!R:P))
B38: Key Risk Metrics
B39: Max Drawdown (approx) | C39: =MIN('Trade Log'!N2:N500)
B40: Trades > 1R Loss | C40: =COUNTIF('Trade Log'!P2:P500,"<-1")
B41: Avg R on Losers | C41: =IFERROR(IF(COUNTIF('Trade Log'!Q:Q,"LOSS")=0,"-",AVERAGEIF('Trade Log'!Q:Q,"LOSS",'Trade Log'!P:P)),"-")
B42: Avg R on Winners | C42: =IFERROR(IF(COUNTIF('Trade Log'!Q:Q,"WIN")=0,"-",AVERAGEIF('Trade Log'!Q:Q,"WIN",'Trade Log'!P:P)),"-")
B43: Median Hold (winners) | C43: =IF(COUNTIF('Trade Log'!Q:Q,"WIN")=0,"-",MEDIAN(IF('Trade Log'!Q2:Q500="WIN",'Trade Log'!R2:R500)))
B44: Median Hold (losers) | C44: =IF(COUNTIF('Trade Log'!Q:Q,"LOSS")=0,"-",MEDIAN(IF('Trade Log'!Q2:Q500="LOSS",'Trade Log'!R2:R500)))

Sheet Daily P&L
A1: Daily P&L Tracker
A2: Date | B2: Trades | C2: Wins | D2: Losses | E2: Win Rate | F2: Gross P&L | G2: Cumulative P&L
A3: 46084 | B3: =IF(A3="","",COUNTIF('Trade Log'!B:B,A3)) | C3: =IF(A3="","",COUNTIFS('Trade Log'!B:B,A3,'Trade Log'!Q:Q,"WIN")) | D3: =IF(A3="","",COUNTIFS('Trade Log'!B:B,A3,'Trade Log'!Q:Q,"LOSS")) | E3: =IF(OR(A3="",B3=0),"-",C3/B3) | F3: =IF(A3="","",SUMIF('Trade Log'!B:B,A3,'Trade Log'!N:N)) | G3: =IF(A3="","",SUM($F$3:F3))
A4: 46085 | B4: =IF(A4="","",COUNTIF('Trade Log'!B:B,A4)) | C4: =IF(A4="","",COUNTIFS('Trade Log'!B:B,A4,'Trade Log'!Q:Q,"WIN")) | D4: =IF(A4="","",COUNTIFS('Trade Log'!B:B,A4,'Trade Log'!Q:Q,"LOSS")) | E4: =IF(OR(A4="",B4=0),"-",C4/B4) | F4: =IF(A4="","",SUMIF('Trade Log'!B:B,A4,'Trade Log'!N:N)) | G4: =IF(A4="","",SUM($F$3:F4))
A5: 46086 | B5: =IF(A5="","",COUNTIF('Trade Log'!B:B,A5)) | C5: =IF(A5="","",COUNTIFS('Trade Log'!B:B,A5,'Trade Log'!Q:Q,"WIN")) | D5: =IF(A5="","",COUNTIFS('Trade Log'!B:B,A5,'Trade Log'!Q:Q,"LOSS")) | E5: =IF(OR(A5="",B5=0),"-",C5/B5) | F5: =IF(A5="","",SUMIF('Trade Log'!B:B,A5,'Trade Log'!N:N)) | G5: =IF(A5="","",SUM($F$3:F5))
B6: =IF(A6="","",COUNTIF('Trade Log'!B:B,A6)) | C6: =IF(A6="","",COUNTIFS('Trade Log'!B:B,A6,'Trade Log'!Q:Q,"WIN")) | D6: =IF(A6="","",COUNTIFS('Trade Log'!B:B,A6,'Trade Log'!Q:Q,"LOSS")) | E6: =IF(OR(A6="",B6=0),"-",C6/B6) | F6: =IF(A6="","",SUMIF('Trade Log'!B:B,A6,'Trade Log'!N:N)) | G6: =IF(A6="","",SUM($F$3:F6))
B7: =IF(A7="","",COUNTIF('Trade Log'!B:B,A7)) | C7: =IF(A7="","",COUNTIFS('Trade Log'!B:B,A7,'Trade Log'!Q:Q,"WIN")) | D7: =IF(A7="","",COUNTIFS('Trade Log'!B:B,A7,'Trade Log'!Q:Q,"LOSS")) | E7: =IF(OR(A7="",B7=0),"-",C7/B7) | F7: =IF(A7="","",SUMIF('Trade Log'!B:B,A7,'Trade Log'!N:N)) | G7: =IF(A7="","",SUM($F$3:F7))
B8: =IF(A8="","",COUNTIF('Trade Log'!B:B,A8)) | C8: =IF(A8="","",COUNTIFS('Trade Log'!B:B,A8,'Trade Log'!Q:Q,"WIN")) | D8: =IF(A8="","",COUNTIFS('Trade Log'!B:B,A8,'Trade Log'!Q:Q,"LOSS")) | E8: =IF(OR(A8="",B8=0),"-",C8/B8) | F8: =IF(A8="","",SUMIF('Trade Log'!B:B,A8,'Trade Log'!N:N)) | G8: =IF(A8="","",SUM($F$3:F8))
B9: =IF(A9="","",COUNTIF('Trade Log'!B:B,A9)) | C9: =IF(A9="","",COUNTIFS('Trade Log'!B:B,A9,'Trade Log'!Q:Q,"WIN")) | D9: =IF(A9="","",COUNTIFS('Trade Log'!B:B,A9,'Trade Log'!Q:Q,"LOSS")) | E9: =IF(OR(A9="",B9=0),"-",C9/B9) | F9: =IF(A9="","",SUMIF('Trade Log'!B:B,A9,'Trade Log'!N:N)) | G9: =IF(A9="","",SUM($F$3:F9))
B10: =IF(A10="","",COUNTIF('Trade Log'!B:B,A10)) | C10: =IF(A10="","",COUNTIFS('Trade Log'!B:B,A10,'Trade Log'!Q:Q,"WIN")) | D10: =IF(A10="","",COUNTIFS('Trade Log'!B:B,A10,'Trade Log'!Q:Q,"LOSS")) | E10: =IF(OR(A10="",B10=0),"-",C10/B10) | F10: =IF(A10="","",SUMIF('Trade Log'!B:B,A10,'Trade Log'!N:N)) | G10: =IF(A10="","",SUM($F$3:F10))
B11: =IF(A11="","",COUNTIF('Trade Log'!B:B,A11)) | C11: =IF(A11="","",COUNTIFS('Trade Log'!B:B,A11,'Trade Log'!Q:Q,"WIN")) | D11: =IF(A11="","",COUNTIFS('Trade Log'!B:B,A11,'Trade Log'!Q:Q,"LOSS")) | E11: =IF(OR(A11="",B11=0),"-",C11/B11) | F11: =IF(A11="","",SUMIF('Trade Log'!B:B,A11,'Trade Log'!N:N)) | G11: =IF(A11="","",SUM($F$3:F11))
B12: =IF(A12="","",COUNTIF('Trade Log'!B:B,A12)) | C12: =IF(A12="","",COUNTIFS('Trade Log'!B:B,A12,'Trade Log'!Q:Q,"WIN")) | D12: =IF(A12="","",COUNTIFS('Trade Log'!B:B,A12,'Trade Log'!Q:Q,"LOSS")) | E12: =IF(OR(A12="",B12=0),"-",C12/B12) | F12: =IF(A12="","",SUMIF('Trade Log'!B:B,A12,'Trade Log'!N:N)) | G12: =IF(A12="","",SUM($F$3:F12))
B13: =IF(A13="","",COUNTIF('Trade Log'!B:B,A13)) | C13: =IF(A13="","",COUNTIFS('Trade Log'!B:B,A13,'Trade Log'!Q:Q,"WIN")) | D13: =IF(A13="","",COUNTIFS('Trade Log'!B:B,A13,'Trade Log'!Q:Q,"LOSS")) | E13: =IF(OR(A13="",B13=0),"-",C13/B13) | F13: =IF(A13="","",SUMIF('Trade Log'!B:B,A13,'Trade Log'!N:N)) | G13: =IF(A13="","",SUM($F$3:F13))
B14: =IF(A14="","",COUNTIF('Trade Log'!B:B,A14)) | C14: =IF(A14="","",COUNTIFS('Trade Log'!B:B,A14,'Trade Log'!Q:Q,"WIN")) | D14: =IF(A14="","",COUNTIFS('Trade Log'!B:B,A14,'Trade Log'!Q:Q,"LOSS")) | E14: =IF(OR(A14="",B14=0),"-",C14/B14) | F14: =IF(A14="","",SUMIF('Trade Log'!B:B,A14,'Trade Log'!N:N)) | G14: =IF(A14="","",SUM($F$3:F14))
B15: =IF(A15="","",COUNTIF('Trade Log'!B:B,A15)) | C15: =IF(A15="","",COUNTIFS('Trade Log'!B:B,A15,'Trade Log'!Q:Q,"WIN")) | D15: =IF(A15="","",COUNTIFS('Trade Log'!B:B,A15,'Trade Log'!Q:Q,"LOSS")) | E15: =IF(OR(A15="",B15=0),"-",C15/B15) | F15: =IF(A15="","",SUMIF('Trade Log'!B:B,A15,'Trade Log'!N:N)) | G15: =IF(A15="","",SUM($F$3:F15))
B16: =IF(A16="","",COUNTIF('Trade Log'!B:B,A16)) | C16: =IF(A16="","",COUNTIFS('Trade Log'!B:B,A16,'Trade Log'!Q:Q,"WIN")) | D16: =IF(A16="","",COUNTIFS('Trade Log'!B:B,A16,'Trade Log'!Q:Q,"LOSS")) | E16: =IF(OR(A16="",B16=0),"-",C16/B16) | F16: =IF(A16="","",SUMIF('Trade Log'!B:B,A16,'Trade Log'!N:N)) | G16: =IF(A16="","",SUM($F$3:F16))
B17: =IF(A17="","",COUNTIF('Trade Log'!B:B,A17)) | C17: =IF(A17="","",COUNTIFS('Trade Log'!B:B,A17,'Trade Log'!Q:Q,"WIN")) | D17: =IF(A17="","",COUNTIFS('Trade Log'!B:B,A17,'Trade Log'!Q:Q,"LOSS")) | E17: =IF(OR(A17="",B17=0),"-",C17/B17) | F17: =IF(A17="","",SUMIF('Trade Log'!B:B,A17,'Trade Log'!N:N)) | G17: =IF(A17="","",SUM($F$3:F17))
... B252: =IF(A252="","",COUNTIF('Trade Log'!B:B,A252)) | C252: =IF(A252="","",COUNTIFS('Trade Log'!B:B,A252,'Trade Log'!Q:Q,"WIN")) | D252: =IF(A252="","",COUNTIFS('Trade Log'!B:B,A252,'Trade Log'!Q:Q,"LOSS")) | E252: =IF(OR(A252="",B252=0),"-",C252/B252) | F252: =IF(A252="","",SUMIF('Trade Log'!B:B,A252,'Trade Log'!N:N)) | G252: =IF(A252="","",SUM($F$3:F252))
